Workbook
Name \0: #REF!
Name \A: #REF!
Name \B: #REF!
Name \C: #REF!
Name \D: #REF!
Name \M: #REF!
Name \P: #REF!
Name \Q: #REF!
Name _: #REF!
Name ____CAP1: #REF!
Name ____CAP2: #REF!
Name ____CAP3: #REF!
Name ____CAP4: #REF!
Name ____CAP5: #REF!
Name ____CAP6: #REF!
Name ____NDE1: #REF!
Name ____NDE2: #REF!
Name ____NDE3: #REF!
Name ____NDE4: #REF!
Name ____NDE5: #REF!
Name ____NDE6: #REF!
Name ___DB1: #REF!
Name ___DB2: #REF!
Name ___DB4: #REF!
Name ___DB6: #REF!
Name ___DB7: #REF!
Name ___INDEX_SHEET___ASAP_Utilities: #REF!
Name ___jba2: #REF!
Name __ANCOUR: #REF!
Name __ANPREC: #REF!
Name __B_1_ERE_ANNN: #REF!
Name __B_AIDE_MEMOI: #REF!
Name __B_GAINNONMAT: #REF!
Name __B_IMPOTEXIGI: #REF!
Name __D_1_ERE_ANNN: #REF!
Name __D_AIDE_MEMOI: #REF!
Name __D_GAINNONMAT: #REF!
Name __D_IMPOTEXIGI: #REF!
Name __DB1: #REF!
Name __DB2: #REF!
Name __DB4: #REF!
Name __DB6: #REF!
Name __DB7: #REF!
Name __DTFIN: #REF!
Name __DTPER: #REF!
Name __jba2: #REF!
Name __SMC9612: #REF!
Name __TITRE: #REF!
Name _1P: #REF!
Name _1st_Pass: #REF!
Name _5Version: #REF!
Name _6Version: #REF!
Name _7Version: #REF!
Name _8Version: #REF!
Name _amo2007: #REF!
Name _B_IMPOTEXI: #REF!
Name _CAP1: #REF!
Name _CAP2: #REF!
Name _CAP3: #REF!
Name _CAP4: #REF!

Sheet FFS Schedule
A1: Category | B1: Sub-Category (INTERNAL ONLY) | C1: Item Name | D1: Per Syringe? | E1: 45688 | F1: =+EOMONTH(E1,1) -> 45716 | G1: =+EOMONTH(F1,1) -> 45747 | H1: =+EOMONTH(G1,1) -> 45777 | I1: =+EOMONTH(H1,1) -> 45808 | J1: =+EOMONTH(I1,1) -> 45838 | K1: =+EOMONTH(J1,1) -> 45869 | L1: =+EOMONTH(K1,1) -> 45900 | M1: =+EOMONTH(L1,1) -> 45930 | ... AB1: =+EOMONTH(AA1,1) -> 46387 | AD1: Latest FFS
A2: Body Contouring | B2: CoolSculpt | C2: CoolSculpting Elite | D2: 0 | E2: =F2 -> 20 | F2: =G2 -> 20 | G2: =H2 -> 20 | H2: 20 | I2: 20 | J2: 20 | K2: =L2 -> 7.5 | L2: 7.5 | M2: 7.5 | N2: 7.5 | O2: 7.5 | P2: 7.5 | Q2: 7.5 | U2: 15 | AD2: {=_xlfn.XLOOKUP(TRUE,E2:AB2<>"",E2:AB2,,,-1)} -> 15
A3: Body Contouring | B3: Cryo - Body Contouring | C3: Cryo Skin 4.0 - Body | D3: 0 | E3: =F3 -> 15 | F3: =G3 -> 15 | G3: =H3 -> 15 | H3: 15 | I3: 15 | J3: 15 | K3: =L3 -> 0 | L3: 0 | M3: 0 | N3: 0 | O3: 0 | P3: 0 | Q3: 0 | U3: 0 | AD3: {=_xlfn.XLOOKUP(TRUE,E3:AB3<>"",E3:AB3,,,-1)} -> 0
A4: Body Contouring | B4: EmSculpt | C4: EMSCULPT NEO | D4: 0 | E4: =F4 -> 5.25 | F4: =G4 -> 5.25 | G4: =H4 -> 5.25 | H4: 5.25 | I4: 5.25 | J4: 5.25 | K4: =L4 -> 5.25 | L4: 5.25 | M4: 5.25 | N4: 5.25 | O4: 5.25 | P4: 5.25 | Q4: 5.25 | U4: 5.25 | AD4: {=_xlfn.XLOOKUP(TRUE,E4:AB4<>"",E4:AB4,,,-1)} -> 5.25
A5: Facials | B5: Clear and Brilliant | C5: Add-on Clear and Brilliant 2nd Area | D5: 0 | E5: =F5 -> 22.2 | F5: =G5 -> 22.2 | G5: =H5 -> 22.2 | H5: 22.2 | I5: 22.2 | J5: 22.2 | K5: =L5 -> 6 | L5: 6 | M5: 6 | N5: 6 | O5: 6 | P5: 6 | Q5: 6 | U5: 6 | AD5: {=_xlfn.XLOOKUP(TRUE,E5:AB5<>"",E5:AB5,,,-1)} -> 6
A6: Facials | B6: Clear and Brilliant | C6: Add-on Clear and Brilliant 3rd Area | D6: 0 | E6: =F6 -> 25.9 | F6: =G6 -> 25.9 | G6: =H6 -> 25.9 | H6: 25.9 | I6: 25.9 | J6: 25.9 | K6: =L6 -> 10 | L6: 10 | M6: 10 | N6: 10 | O6: 10 | P6: 10 | Q6: 10 | U6: 10 | AD6: {=_xlfn.XLOOKUP(TRUE,E6:AB6<>"",E6:AB6,,,-1)} -> 10
A7: Facials | B7: Other Chemical Peels | C7: Chemical Peel | D7: 0 | E7: =F7 -> 11.1 | F7: =G7 -> 11.1 | G7: =H7 -> 11.1 | H7: 11.1 | I7: 11.1 | J7: 11.1 | K7: =L7 -> 0 | L7: 0 | M7: 0 | N7: 0 | O7: 0 | P7: 0 | Q7: 0 | U7: 0 | AD7: {=_xlfn.XLOOKUP(TRUE,E7:AB7<>"",E7:AB7,,,-1)} -> 0
A8: Facials | B8: SkinMedica | C8: Chemical Peel (SkinMedica) | D8: 0 | E8: =F8 -> 11.1 | F8: =G8 -> 11.1 | G8: =H8 -> 11.1 | H8: 11.1 | I8: 11.1 | J8: 11.1 | K8: =L8 -> 0 | L8: 0 | M8: 0 | N8: 0 | O8: 0 | P8: 0 | Q8: 0 | U8: 0 | AD8: {=_xlfn.XLOOKUP(TRUE,E8:AB8<>"",E8:AB8,,,-1)} -> 0
A9: Facials | B9: Clear and Brilliant | C9: Clear and Brilliant 1 Treatment Area (Face, Neck or Chest) | D9: 0 | E9: =F9 -> 16.65 | F9: =G9 -> 16.65 | G9: =H9 -> 16.65 | H9: 16.65 | I9: 16.65 | J9: 16.65 | K9: =L9 -> 12 | L9: 12 | M9: 12 | N9: 12 | O9: 12 | P9: 12 | Q9: 12 | U9: 12 | AD9: {=_xlfn.XLOOKUP(TRUE,E9:AB9<>"",E9:AB9,,,-1)} -> 12
A10: Facials | B10: Cryo - Facials | C10: CryoSkin 4.0 Facial | D10: 0 | E10: =F10 -> 6.75 | F10: =G10 -> 6.75 | G10: =H10 -> 6.75 | H10: 6.75 | I10: 6.75 | J10: 6.75 | K10: =L10 -> 3 | L10: 3 | M10: 3 | N10: 3 | O10: 3 | P10: 3 | Q10: 3 | U10: 3 | AD10: {=_xlfn.XLOOKUP(TRUE,E10:AB10<>"",E10:AB10,,,-1)} -> 3
A11: Facials | B11: Deep Pore Facial | C11: Deep Pore Facial | D11: 0 | E11: =F11 -> 11.25 | F11: =G11 -> 11.25 | G11: =H11 -> 11.25 | H11: 11.25 | I11: 11.25 | J11: 11.25 | K11: =L11 -> 9 | L11: 9 | M11: 9 | N11: 9 | O11: 9 | P11: 9 | Q11: 9 | U11: 9 | AD11: {=_xlfn.XLOOKUP(TRUE,E11:AB11<>"",E11:AB11,,,-1)} -> 9
A12: Facials | B12: Dermaplane | C12: Dermaplane Add-on | D12: 0 | E12: =F12 -> 5 | F12: =G12 -> 5 | G12: =H12 -> 5 | H12: 5 | I12: 5 | J12: 5 | K12: =L12 -> 5 | L12: 5 | M12: 5 | N12: 5 | O12: 5 | P12: 5 | Q12: 5 | U12: 5 | AD12: {=_xlfn.XLOOKUP(TRUE,E12:AB12<>"",E12:AB12,,,-1)} -> 5
A13: Facials | B13: Dermaplane | C13: Dermaplaning | D13: 0 | E13: =F13 -> 6.75 | F13: =G13 -> 6.75 | G13: =H13 -> 6.75 | H13: 6.75 | I13: 6.75 | J13: 6.75 | K13: =L13 -> 6.75 | L13: 6.75 | M13: 6.75 | N13: 6.75 | O13: 6.75 | P13: 6.75 | Q13: 6.75 | U13: 6.75 | AD13: {=_xlfn.XLOOKUP(TRUE,E13:AB13<>"",E13:AB13,,,-1)} -> 6.75
... A36: Facials | B36: Hydrafacial | C36: Hydrafacial - Lip Perk Add-On | D36: 0 | E36: =F36 -> 0 | F36: =G36 -> 0 | G36: =H36 -> 0 | H36: 0 | I36: 0 | J36: 0 | K36: =L36 -> 2.25 | L36: 2.25 | M36: 2.25 | N36: 2.25 | O36: 2.25 | P36: 2.25 | Q36: 2.25 | U36: 2.25 | AD36: {=_xlfn.XLOOKUP(TRUE,E36:AB36<>"",E36:AB36,,,-1)} -> 2.25
A37: Filler | B37: Belotero | C37: Belotero (Balance) | D37: Y | E37: =F37 -> 25 | F37: =G37 -> 25 | G37: =H37 -> 25 | H37: 25 | I37: 25 | J37: 25 | K37: =L37 -> 25 | L37: 25 | M37: 25 | N37: 25 | O37: 25 | P37: 25 | Q37: 25 | U37: 25 | AD37: {=_xlfn.XLOOKUP(TRUE,E37:AB37<>"",E37:AB37,,,-1)} -> 25
A38: Filler | B38: Other Filler | C38: Dermal Fillers | D38: 0 | E38: =F38 -> 0 | F38: =G38 -> 0 | G38: =H38 -> 0 | H38: 0 | I38: 0 | J38: 0 | K38: =L38 -> 0 | L38: 0 | M38: 0 | N38: 0 | O38: 0 | P38: 0 | Q38: 0 | U38: 0 | AD38: {=_xlfn.XLOOKUP(TRUE,E38:AB38<>"",E38:AB38,,,-1)} -> 0
A39: Filler | B39: Hylenex | C39: Hylenex | D39: 0 | E39: =F39 -> 5 | F39: =G39 -> 5 | G39: =H39 -> 5 | H39: 5 | I39: 5 | J39: 5 | K39: =L39 -> 5 | L39: 5 | M39: 5 | N39: 5 | O39: 5 | P39: 5 | Q39: 5 | U39: 5 | AD39: {=_xlfn.XLOOKUP(TRUE,E39:AB39<>"",E39:AB39,,,-1)} -> 5
A40: Filler | B40: Juvederm | C40: Juvederm (Ultra Plus) | D40: Y | E40: =F40 -> 19.8 | F40: =G40 -> 19.8 | G40: =H40 -> 19.8 | H40: 19.8 | I40: 19.8 | J40: 19.8 | K40: =L40 -> 5 | L40: 5 | M40: 5 | N40: 5 | O40: 5 | P40: 5 | Q40: 5 | U40: 5 | AD40: {=_xlfn.XLOOKUP(TRUE,E40:AB40<>"",E40:AB40,,,-1)} -> 5
A41: Filler | B41: Juvederm | C41: Juvederm (Ultra) | D41: Y | E41: =F41 -> 19.8 | F41: =G41 -> 19.8 | G41: =H41 -> 19.8 | H41: 19.8 | I41: 19.8 | J41: 19.8 | K41: =L41 -> 5 | L41: 5 | M41: 5 | N41: 5 | O41: 5 | P41: 5 | Q41: 5 | U41: 5 | AD41: {=_xlfn.XLOOKUP(TRUE,E41:AB41<>"",E41:AB41,,,-1)} -> 5
A42: Filler | B42: Juvederm | C42: Juvederm (Volbella) | D42: Y | E42: =F42 -> 19.8 | F42: =G42 -> 19.8 | G42: =H42 -> 19.8 | H42: 19.8 | I42: 19.8 | J42: 19.8 | K42: =L42 -> 5 | L42: 5 | M42: 5 | N42: 5 | O42: 5 | P42: 5 | Q42: 5 | U42: 5 | AD42: {=_xlfn.XLOOKUP(TRUE,E42:AB42<>"",E42:AB42,,,-1)} -> 5
A43: Filler | B43: Juvederm | C43: Juvederm (Vollure) | D43: Y | E43: =F43 -> 19.8 | F43: =G43 -> 19.8 | G43: =H43 -> 19.8 | H43: 19.8 | I43: 19.8 | J43: 19.8 | K43: =L43 -> 5 | L43: 5 | M43: 5 | N43: 5 | O43: 5 | P43: 5 | Q43: 5 | U43: 5 | AD43: {=_xlfn.XLOOKUP(TRUE,E43:AB43<>"",E43:AB43,,,-1)} -> 5
A44: Filler | B44: Juvederm | C44: Juvederm (Voluma) | D44: Y | E44: =F44 -> 15 | F44: =G44 -> 15 | G44: =H44 -> 15 | H44: 15 | I44: 15 | J44: 15 | K44: =L44 -> 5 | L44: 5 | M44: 5 | N44: 5 | O44: 5 | P44: 5 | Q44: 5 | U44: 5 | AD44: {=_xlfn.XLOOKUP(TRUE,E44:AB44<>"",E44:AB44,,,-1)} -> 5
A45: Filler | B45: Juvederm | C45: Juvederm Half Syringe (Ultra) | D45: Y | E45: =F45 -> 15 | F45: =G45 -> 15 | G45: =H45 -> 15 | H45: 15 | I45: 15 | J45: 15 | K45: =L45 -> 5 | L45: 5 | M45: 5 | N45: 5 | O45: 5 | P45: 5 | Q45: 5 | U45: 5 | AD45: {=_xlfn.XLOOKUP(TRUE,E45:AB45<>"",E45:AB45,,,-1)} -> 5
A46: Filler | B46: Juvederm | C46: Juvederm Upcharge 100 | D46: 0 | E46: =F46 -> 0 | F46: =G46 -> 0 | G46: =H46 -> 0 | H46: 0 | I46: 0 | J46: 0 | K46: =L46 -> 0 | L46: 0 | M46: 0 | N46: 0 | O46: 0 | P46: 0 | Q46: 0 | U46: 0 | AD46: {=_xlfn.XLOOKUP(TRUE,E46:AB46<>"",E46:AB46,,,-1)} -> 0
A47: Filler | B47: Juvederm | C47: Juvederm Volbella (Half Syringe) | D47: Y | E47: =F47 -> 15 | F47: =G47 -> 15 | G47: =H47 -> 15 | H47: 15 | I47: 15 | J47: 15 | K47: =L47 -> 5 | L47: 5 | M47: 5 | N47: 5 | O47: 5 | P47: 5 | Q47: 5 | U47: 5 | AD47: {=_xlfn.XLOOKUP(TRUE,E47:AB47<>"",E47:AB47,,,-1)} -> 5
A48: Filler | B48: Juvederm | C48: Juvederm Volux | D48: Y | E48: =F48 -> 15 | F48: =G48 -> 15 | G48: =H48 -> 15 | H48: 15 | I48: 15 | J48: 15 | K48: =L48 -> 5 | L48: 5 | M48: 5 | N48: 5 | O48: 5 | P48: 5 | Q48: 5 | U48: 5 | AD48: {=_xlfn.XLOOKUP(TRUE,E48:AB48<>"",E48:AB48,,,-1)} -> 5
A49: Filler | B49: Kybella | C49: Kybella Double Chin Treatment | D49: Y | E49: =F49 -> 13.2 | F49: =G49 -> 13.2 | G49: =H49 -> 13.2 | H49: 13.2 | I49: 13.2 | J49: 13.2 | K49: =L49 -> 15 | L49: 15 | M49: 15 | N49: 15 | O49: 15 | P49: 15 | Q49: 15 | U49: 15 | AD49: {=_xlfn.XLOOKUP(TRUE,E49:AB49<>"",E49:AB49,,,-1)} -> 15
A50: Filler | B50: Other Filler | C50: Lip Filler | D50: 0 | E50: =F50 -> 0 | F50: =G50 -> 0 | G50: =H50 -> 0 | H50: 0 | I50: 0 | J50: 0 | K50: =L50 -> 0 | L50: 0 | M50: 0 | N50: 0 | O50: 0 | P50: 0 | Q50: 0 | U50: 0 | AD50: {=_xlfn.XLOOKUP(TRUE,E50:AB50<>"",E50:AB50,,,-1)} -> 0
A51: Filler | B51: Radiesse | C51: Non-Surgical Brazilian Butt Lift Mini (Radiesse) | D51: 0 | E51: =F51 -> 150 | F51: =G51 -> 150 | G51: =H51 -> 150 | H51: 150 | I51: 150 | J51: 150 | K51: =L51 -> 150 | L51: 150 | M51: 150 | N51: 150 | O51: 150 | P51: 150 | Q51: 150 | U51: 150 | AD51: {=_xlfn.XLOOKUP(TRUE,E51:AB51<>"",E51:AB51,,,-1)} -> 150
A52: Filler | B52: Radiesse | C52: Non-Surgical Brazilian Butt Lift Ultimate (Radiesse) | D52: 0 | E52: =F52 -> 300 | F52: =G52 -> 300 | G52: =H52 -> 300 | H52: 300 | I52: 300 | J52: 300 | K52: =L52 -> 300 | L52: 300 | M52: 300 | N52: 300 | O52: 300 | P52: 300 | Q52: 300 | U52: 300 | AD52: {=_xlfn.XLOOKUP(TRUE,E52:AB52<>"",E52:AB52,,,-1)} -> 300
A53: Filler | B53: Radiesse | C53: Non-Surgical Mini BBL Radiesse | D53: 0 | E53: =F53 -> 150 | F53: =G53 -> 150 | G53: =H53 -> 150 | H53: 150 | I53: 150 | J53: 150 | K53: =L53 -> 150 | L53: 150 | M53: 150 | N53: 150 | O53: 150 | P53: 150 | Q53: 150 | U53: 150 | AD53: {=_xlfn.XLOOKUP(TRUE,E53:AB53<>"",E53:AB53,,,-1)} -> 150
A54: Filler | B54: Radiesse | C54: Non-Surgical Ultimate BBL Radiesse | D54: 0 | E54: =F54 -> 300 | F54: =G54 -> 300 | G54: =H54 -> 300 | H54: 300 | I54: 300 | J54: 300 | K54: =L54 -> 300 | L54: 300 | M54: 300 | N54: 300 | O54: 300 | P54: 300 | Q54: 300 | U54: 300 | AD54: {=_xlfn.XLOOKUP(TRUE,E54:AB54<>"",E54:AB54,,,-1)} -> 300
A55: Filler | B55: Radiesse | C55: Radiesse | D55: Y | E55: =F55 -> 25 | F55: =G55 -> 25 | G55: =H55 -> 25 | H55: 25 | I55: 25 | J55: 25 | K55: =L55 -> 20 | L55: 20 | M55: 20 | N55: 20 | O55: 20 | P55: 20 | Q55: 20 | U55: 20 | AD55: {=_xlfn.XLOOKUP(TRUE,E55:AB55<>"",E55:AB55,,,-1)} -> 20
A56: Filler | B56: Radiesse | C56: Radiesse (with Lidocaine) | D56: Y | E56: =F56 -> 25 | F56: =G56 -> 25 | G56: =H56 -> 25 | H56: 25 | I56: 25 | J56: 25 | K56: =L56 -> 20 | L56: 20 | M56: 20 | N56: 20 | O56: 20 | P56: 20 | Q56: 20 | U56: 20 | AD56: {=_xlfn.XLOOKUP(TRUE,E56:AB56<>"",E56:AB56,,,-1)} -> 20
A57: Filler | B57: Restylane | C57: Restylane - L | D57: Y | E57: =F57 -> 19.8 | F57: =G57 -> 19.8 | G57: =H57 -> 19.8 | H57: 19.8 | I57: 19.8 | J57: 19.8 | K57: =L57 -> 12.5 | L57: 12.5 | M57: 12.5 | N57: 12.5 | O57: 12.5 | P57: 12.5 | Q57: 12.5 | U57: 12.5 | AD57: {=_xlfn.XLOOKUP(TRUE,E57:AB57<>"",E57:AB57,,,-1)} -> 12.5
A58: Filler | B58: Restylane | C58: Restylane (Contour) | D58: Y | E58: =F58 -> 19.8 | F58: =G58 -> 19.8 | G58: =H58 -> 19.8 | H58: 19.8 | I58: 19.8 | J58: 19.8 | K58: =L58 -> 12.5 | L58: 12.5 | M58: 12.5 | N58: 12.5 | O58: 12.5 | P58: 12.5 | Q58: 12.5 | U58: 12.5 | AD58: {=_xlfn.XLOOKUP(TRUE,E58:AB58<>"",E58:AB58,,,-1)} -> 12.5
A59: Filler | B59: Restylane | C59: Restylane Defyne | D59: Y | E59: =F59 -> 19.8 | F59: =G59 -> 19.8 | G59: =H59 -> 19.8 | H59: 19.8 | I59: 19.8 | J59: 19.8 | K59: =L59 -> 12.5 | L59: 12.5 | M59: 12.5 | N59: 12.5 | O59: 12.5 | P59: 12.5 | Q59: 12.5 | U59: 12.5 | AD59: {=_xlfn.XLOOKUP(TRUE,E59:AB59<>"",E59:AB59,,,-1)} -> 12.5
A60: Filler | B60: Restylane | C60: Restylane Kysse | D60: Y | E60: =F60 -> 19.8 | F60: =G60 -> 19.8 | G60: =H60 -> 19.8 | H60: 19.8 | I60: 19.8 | J60: 19.8 | K60: =L60 -> 12.5 | L60: 12.5 | M60: 12.5 | N60: 12.5 | O60: 12.5 | P60: 12.5 | Q60: 12.5 | U60: 12.5 | AD60: {=_xlfn.XLOOKUP(TRUE,E60:AB60<>"",E60:AB60,,,-1)} -> 12.5
A61: Filler | B61: Restylane | C61: Restylane Lyft | D61: Y | E61: =F61 -> 19.8 | F61: =G61 -> 19.8 | G61: =H61 -> 19.8 | H61: 19.8 | I61: 19.8 | J61: 19.8 | K61: =L61 -> 15 | L61: 15 | M61: 15 | N61: 15 | O61: 15 | P61: 15 | Q61: 15 | U61: 15 | AD61: {=_xlfn.XLOOKUP(TRUE,E61:AB61<>"",E61:AB61,,,-1)} -> 15
A62: Filler | B62: Restylane | C62: Restylane Refyne | D62: Y | E62: =F62 -> 19.8 | F62: =G62 -> 19.8 | G62: =H62 -> 19.8 | H62: 19.8 | I62: 19.8 | J62: 19.8 | K62: =L62 -> 12.5 | L62: 12.5 | M62: 12.5 | N62: 12.5 | O62: 12.5 | P62: 12.5 | Q62: 12.5 | U62: 12.5 | AD62: {=_xlfn.XLOOKUP(TRUE,E62:AB62<>"",E62:AB62,,,-1)} -> 12.5
...

Sheet Hourly Wage
C1: 0.125
A2: Employee Role | B2: Hourly Rate | C2: Hourly Rate (Fully Burdened) | D2: Hourly Rate (Utilization Adj.) | E2: Avg. Utilization
A3: Body Contouring Expert | B3: 25.454545 | C3: =+B3*(1+C$1) -> 28.636364 | D3: =+IFERROR(C3/E3,C3) -> 28.636364 | E3: n/a
A4: Clinic DirectorConcierge | B4: 20.777778 | C4: =+B4*(1+C$1) -> 23.375 | D4: =+IFERROR(C4/E4,C4) -> 23.375 | E4: n/a
A5: Esthetician | B5: 25.454545 | C5: =+B5*(1+C$1) -> 28.636364 | D5: =+IFERROR(C5/E5,C5) -> 52.066116 | E5: 0.55
A6: Manager | B6: 30.542857 | C6: =+B6*(1+C$1) -> 34.360714 | D6: =+IFERROR(C6/E6,C6) -> 34.360714 | E6: n/a
A7: THERAPIST | B7: 62.321852 | C7: =+B7*(1+C$1) -> 70.112083 | D7: =+IFERROR(C7/E7,C7) -> 100.16012 | E7: 0.7
A8: Treatment Provider | B8: 62.321852 | C8: =+B8*(1+C$1) -> 70.112083 | D8: =+IFERROR(C8/E8,C8) -> 100.16012 | E8: 0.7
A9: Clinical Leadership Team | B9: 0 | C9: =+B9 -> 0 | D9: =+IFERROR(C9/E9,C9) -> 0 | E9: 1
A10: VP of Clinical | B10: =250000/2080 -> 120.19231 | C10: =+B10*(1+C$1) -> 135.21635 | D10: =+IFERROR(C10/E10,C10) -> 135.21635 | E10: 1
A11: Head MD | B11: 125 | C11: =+B11 -> 125 | D11: =+IFERROR(C11/E11,C11) -> 125 | E11: 1

Sheet Operating Schedule
C2: =EOMONTH(C3,0) -> 46053 | D2: =EOMONTH(D3,0) -> 46053 | E2: =EOMONTH(E3,0) -> 46053 | F2: =EOMONTH(F3,0) -> 46053 | G2: =EOMONTH(G3,0) -> 46053 | H2: =EOMONTH(H3,0) -> 46053 | I2: =EOMONTH(I3,0) -> 46053 | J2: =EOMONTH(J3,0) -> 46053 | ... NC2: =EOMONTH(NC3,0) -> 46387
B3: Daily | C3: 46023 | D3: =+C3+1 -> 46024 | E3: =+D3+1 -> 46025 | F3: =+E3+1 -> 46026 | G3: =+F3+1 -> 46027 | H3: =+G3+1 -> 46028 | I3: =+H3+1 -> 46029 | J3: =+I3+1 -> 46030 | K3: =+J3+1 -> 46031 | ... NC3: =+NB3+1 -> 46387
C4: =WEEKDAY(C3,1) -> 5 | D4: =WEEKDAY(D3,1) -> 6 | E4: =WEEKDAY(E3,1) -> 7 | F4: =WEEKDAY(F3,1) -> 1 | G4: =WEEKDAY(G3,1) -> 2 | H4: =WEEKDAY(H3,1) -> 3 | I4: =WEEKDAY(I3,1) -> 4 | J4: =WEEKDAY(J3,1) -> 5 | ... NC4: =WEEKDAY(NC3,1) -> 5
C5: =TEXT(C4,"DDDD") -> Thursday | D5: =TEXT(D4,"DDDD") -> Friday | E5: =TEXT(E4,"DDDD") -> Saturday | F5: =TEXT(F4,"DDDD") -> Sunday | G5: =TEXT(G4,"DDDD") -> Monday | H5: =TEXT(H4,"DDDD") -> Tuesday | I5: =TEXT(I4,"DDDD") -> Wednesday | J5: =TEXT(J4,"DDDD") -> Thursday | ... NC5: =TEXT(NC4,"DDDD") -> Thursday
B6: Denville, NJ | C6: 0 | D6: =IF(SUMIFS('Locations Data'!$C:$C,'Locations Data'!$G:$G,$B6,'Locations Data'!$B:$B,D$5)>0,1,0) -> 1 | E6: =IF(SUMIFS('Locations Data'!$C:$C,'Locations Data'!$G:$G,$B6,'Locations Data'!$B:$B,E$5)>0,1,0) -> 1 | F6: =IF(SUMIFS('Locations Data'!$C:$C,'Locations Data'!$G:$G,$B6,'Locations Data'!$B:$B,F$5)>0,1,0) -> 0 | G6: =IF(SUMIFS('Locations Data'!$C:$C,'Locations Data'!$G:$G,$B6,'Locations Data'!$B:$B,G$5)>0,1,0) -> 1 | H6: =IF(SUMIFS('Locations Data'!$C:$C,'Locations Data'!$G:$G,$B6,'Locations Data'!$B:$B,H$5)>0,1,0) -> 1 | I6: =IF(SUMIFS('Locations Data'!$C:$C,'Locations Data'!$G:$G,$B6,'Locations Data'!$B:$B,I$5)>0,1,0) -> 1 | J6: =IF(SUMIFS('Locations Data'!$C:$C,'Locations Data'!$G:$G,$B6,'Locations Data'!$B:$B,J$5)>0,1,0) -> 1 | K6: =IF(SUMIFS('Locations Data'!$C:$C,'Locations Data'!$G:$G,$B6,'Locations Data'!$B:$B,K$5)>0,1,0) -> 1 | ... MV6: =IF(SUMIFS('Locations Data'!$C:$C,'Locations Data'!$G:$G,$B6,'Locations Data'!$B:$B,MV$5)>0,1,0) -> 1 | MW6: 0 | MX6: =IF(SUMIFS('Locations Data'!$C:$C,'Locations Data'!$G:$G,$B6,'Locations Data'!$B:$B,MX$5)>0,1,0) -> 1 | MY6: =IF(SUMIFS('Locations Data'!$C:$C,'Locations Data'!$G:$G,$B6,'Locations Data'!$B:$B,MY$5)>0,1,0) -> 0 | MZ6: =IF(SUMIFS('Locations Data'!$C:$C,'Locations Data'!$G:$G,$B6,'Locations Data'!$B:$B,MZ$5)>0,1,0) -> 1 | NA6: =IF(SUMIFS('Locations Data'!$C:$C,'Locations Data'!$G:$G,$B6,'Locations Data'!$B:$B,NA$5)>0,1,0) -> 1 | NB6: =IF(SUMIFS('Locations Data'!$C:$C,'Locations Data'!$G:$G,$B6,'Locations Data'!$B:$B,NB$5)>0,1,0) -> 1 | NC6: =IF(SUMIFS('Locations Data'!$C:$C,'Locations Data'!$G:$G,$B6,'Locations Data'!$B:$B,NC$5)>0,1,0) -> 1
B7: Hoboken, NJ | C7: 0 | D7: =IF(SUMIFS('Locations Data'!$C:$C,'Locations Data'!$G:$G,$B7,'Locations Data'!$B:$B,D$5)>0,1,0) -> 1 | E7: =IF(SUMIFS('Locations Data'!$C:$C,'Locations Data'!$G:$G,$B7,'Locations Data'!$B:$B,E$5)>0,1,0) -> 1 | F7: =IF(SUMIFS('Locations Data'!$C:$C,'Locations Data'!$G:$G,$B7,'Locations Data'!$B:$B,F$5)>0,1,0) -> 0 | G7: =IF(SUMIFS('Locations Data'!$C:$C,'Locations Data'!$G:$G,$B7,'Locations Data'!$B:$B,G$5)>0,1,0) -> 1 | H7: =IF(SUMIFS('Locations Data'!$C:$C,'Locations Data'!$G:$G,$B7,'Locations Data'!$B:$B,H$5)>0,1,0) -> 1 | I7: =IF(SUMIFS('Locations Data'!$C:$C,'Locations Data'!$G:$G,$B7,'Locations Data'!$B:$B,I$5)>0,1,0) -> 1 | J7: =IF(SUMIFS('Locations Data'!$C:$C,'Locations Data'!$G:$G,$B7,'Locations Data'!$B:$B,J$5)>0,1,0) -> 1 | K7: =IF(SUMIFS('Locations Data'!$C:$C,'Locations Data'!$G:$G,$B7,'Locations Data'!$B:$B,K$5)>0,1,0) -> 1 | ... MV7: =IF(SUMIFS('Locations Data'!$C:$C,'Locations Data'!$G:$G,$B7,'Locations Data'!$B:$B,MV$5)>0,1,0) -> 1 | MW7: 0 | MX7: =IF(SUMIFS('Locations Data'!$C:$C,'Locations Data'!$G:$G,$B7,'Locations Data'!$B:$B,MX$5)>0,1,0) -> 1 | MY7: =IF(SUMIFS('Locations Data'!$C:$C,'Locations Data'!$G:$G,$B7,'Locations Data'!$B:$B,MY$5)>0,1,0) -> 0 | MZ7: =IF(SUMIFS('Locations Data'!$C:$C,'Locations Data'!$G:$G,$B7,'Locations Data'!$B:$B,MZ$5)>0,1,0) -> 1 | NA7: =IF(SUMIFS('Locations Data'!$C:$C,'Locations Data'!$G:$G,$B7,'Locations Data'!$B:$B,NA$5)>0,1,0) -> 1 | NB7: =IF(SUMIFS('Locations Data'!$C:$C,'Locations Data'!$G:$G,$B7,'Locations Data'!$B:$B,NB$5)>0,1,0) -> 1 | NC7: =IF(SUMIFS('Locations Data'!$C:$C,'Locations Data'!$G:$G,$B7,'Locations Data'!$B:$B,NC$5)>0,1,0) -> 1
B8: Jersey City, NJ | C8: 0 | D8: =IF(SUMIFS('Locations Data'!$C:$C,'Locations Data'!$G:$G,$B8,'Locations Data'!$B:$B,D$5)>0,1,0) -> 1 | E8: =IF(SUMIFS('Locations Data'!$C:$C,'Locations Data'!$G:$G,$B8,'Locations Data'!$B:$B,E$5)>0,1,0) -> 1 | F8: =IF(SUMIFS('Locations Data'!$C:$C,'Locations Data'!$G:$G,$B8,'Locations Data'!$B:$B,F$5)>0,1,0) -> 0 | G8: =IF(SUMIFS('Locations Data'!$C:$C,'Locations Data'!$G:$G,$B8,'Locations Data'!$B:$B,G$5)>0,1,0) -> 1 | H8: =IF(SUMIFS('Locations Data'!$C:$C,'Locations Data'!$G:$G,$B8,'Locations Data'!$B:$B,H$5)>0,1,0) -> 1 | I8: =IF(SUMIFS('Locations Data'!$C:$C,'Locations Data'!$G:$G,$B8,'Locations Data'!$B:$B,I$5)>0,1,0) -> 1 | J8: =IF(SUMIFS('Locations Data'!$C:$C,'Locations Data'!$G:$G,$B8,'Locations Data'!$B:$B,J$5)>0,1,0) -> 1 | K8: =IF(SUMIFS('Locations Data'!$C:$C,'Locations Data'!$G:$G,$B8,'Locations Data'!$B:$B,K$5)>0,1,0) -> 1 | ... MV8: =IF(SUMIFS('Locations Data'!$C:$C,'Locations Data'!$G:$G,$B8,'Locations Data'!$B:$B,MV$5)>0,1,0) -> 1 | MW8: 0 | MX8: =IF(SUMIFS('Locations Data'!$C:$C,'Locations Data'!$G:$G,$B8,'Locations Data'!$B:$B,MX$5)>0,1,0) -> 1 | MY8: =IF(SUMIFS('Locations Data'!$C:$C,'Locations Data'!$G:$G,$B8,'Locations Data'!$B:$B,MY$5)>0,1,0) -> 0 | MZ8: =IF(SUMIFS('Locations Data'!$C:$C,'Locations Data'!$G:$G,$B8,'Locations Data'!$B:$B,MZ$5)>0,1,0) -> 1 | NA8: =IF(SUMIFS('Locations Data'!$C:$C,'Locations Data'!$G:$G,$B8,'Locations Data'!$B:$B,NA$5)>0,1,0) -> 1 | NB8: =IF(SUMIFS('Locations Data'!$C:$C,'Locations Data'!$G:$G,$B8,'Locations Data'!$B:$B,NB$5)>0,1,0) -> 1 | NC8: =IF(SUMIFS('Locations Data'!$C:$C,'Locations Data'!$G:$G,$B8,'Locations Data'!$B:$B,NC$5)>0,1,0) -> 1
B9: Red Bank, NJ | C9: 0 | D9: =IF(SUMIFS('Locations Data'!$C:$C,'Locations Data'!$G:$G,$B9,'Locations Data'!$B:$B,D$5)>0,1,0) -> 1 | E9: =IF(SUMIFS('Locations Data'!$C:$C,'Locations Data'!$G:$G,$B9,'Locations Data'!$B:$B,E$5)>0,1,0) -> 1 | F9: =IF(SUMIFS('Locations Data'!$C:$C,'Locations Data'!$G:$G,$B9,'Locations Data'!$B:$B,F$5)>0,1,0) -> 0 | G9: =IF(SUMIFS('Locations Data'!$C:$C,'Locations Data'!$G:$G,$B9,'Locations Data'!$B:$B,G$5)>0,1,0) -> 0 | H9: =IF(SUMIFS('Locations Data'!$C:$C,'Locations Data'!$G:$G,$B9,'Locations Data'!$B:$B,H$5)>0,1,0) -> 1 | I9: =IF(SUMIFS('Locations Data'!$C:$C,'Locations Data'!$G:$G,$B9,'Locations Data'!$B:$B,I$5)>0,1,0) -> 1 | J9: =IF(SUMIFS('Locations Data'!$C:$C,'Locations Data'!$G:$G,$B9,'Locations Data'!$B:$B,J$5)>0,1,0) -> 1 | K9: =IF(SUMIFS('Locations Data'!$C:$C,'Locations Data'!$G:$G,$B9,'Locations Data'!$B:$B,K$5)>0,1,0) -> 1 | ... MV9: =IF(SUMIFS('Locations Data'!$C:$C,'Locations Data'!$G:$G,$B9,'Locations Data'!$B:$B,MV$5)>0,1,0) -> 1 | MW9: 0 | MX9: =IF(SUMIFS('Locations Data'!$C:$C,'Locations Data'!$G:$G,$B9,'Locations Data'!$B:$B,MX$5)>0,1,0) -> 1 | MY9: =IF(SUMIFS('Locations Data'!$C:$C,'Locations Data'!$G:$G,$B9,'Locations Data'!$B:$B,MY$5)>0,1,0) -> 0 | MZ9: =IF(SUMIFS('Locations Data'!$C:$C,'Locations Data'!$G:$G,$B9,'Locations Data'!$B:$B,MZ$5)>0,1,0) -> 0 | NA9: =IF(SUMIFS('Locations Data'!$C:$C,'Locations Data'!$G:$G,$B9,'Locations Data'!$B:$B,NA$5)>0,1,0) -> 1 | NB9: =IF(SUMIFS('Locations Data'!$C:$C,'Locations Data'!$G:$G,$B9,'Locations Data'!$B:$B,NB$5)>0,1,0) -> 1 | NC9: =IF(SUMIFS('Locations Data'!$C:$C,'Locations Data'!$G:$G,$B9,'Locations Data'!$B:$B,NC$5)>0,1,0) -> 1
B10: Tribeca, NY | C10: 0 | D10: =IF(SUMIFS('Locations Data'!$C:$C,'Locations Data'!$G:$G,$B10,'Locations Data'!$B:$B,D$5)>0,1,0) -> 1 | E10: =IF(SUMIFS('Locations Data'!$C:$C,'Locations Data'!$G:$G,$B10,'Locations Data'!$B:$B,E$5)>0,1,0) -> 0 | F10: =IF(SUMIFS('Locations Data'!$C:$C,'Locations Data'!$G:$G,$B10,'Locations Data'!$B:$B,F$5)>0,1,0) -> 0 | G10: =IF(SUMIFS('Locations Data'!$C:$C,'Locations Data'!$G:$G,$B10,'Locations Data'!$B:$B,G$5)>0,1,0) -> 1 | H10: =IF(SUMIFS('Locations Data'!$C:$C,'Locations Data'!$G:$G,$B10,'Locations Data'!$B:$B,H$5)>0,1,0) -> 1 | I10: =IF(SUMIFS('Locations Data'!$C:$C,'Locations Data'!$G:$G,$B10,'Locations Data'!$B:$B,I$5)>0,1,0) -> 1 | J10: =IF(SUMIFS('Locations Data'!$C:$C,'Locations Data'!$G:$G,$B10,'Locations Data'!$B:$B,J$5)>0,1,0) -> 1 | K10: =IF(SUMIFS('Locations Data'!$C:$C,'Locations Data'!$G:$G,$B10,'Locations Data'!$B:$B,K$5)>0,1,0) -> 1 | ... MV10: =IF(SUMIFS('Locations Data'!$C:$C,'Locations Data'!$G:$G,$B10,'Locations Data'!$B:$B,MV$5)>0,1,0) -> 1 | MW10: 0 | MX10: =IF(SUMIFS('Locations Data'!$C:$C,'Locations Data'!$G:$G,$B10,'Locations Data'!$B:$B,MX$5)>0,1,0) -> 0 | MY10: =IF(SUMIFS('Locations Data'!$C:$C,'Locations Data'!$G:$G,$B10,'Locations Data'!$B:$B,MY$5)>0,1,0) -> 0 | MZ10: =IF(SUMIFS('Locations Data'!$C:$C,'Locations Data'!$G:$G,$B10,'Locations Data'!$B:$B,MZ$5)>0,1,0) -> 1 | NA10: =IF(SUMIFS('Locations Data'!$C:$C,'Locations Data'!$G:$G,$B10,'Locations Data'!$B:$B,NA$5)>0,1,0) -> 1 | NB10: =IF(SUMIFS('Locations Data'!$C:$C,'Locations Data'!$G:$G,$B10,'Locations Data'!$B:$B,NB$5)>0,1,0) -> 1 | NC10: =IF(SUMIFS('Locations Data'!$C:$C,'Locations Data'!$G:$G,$B10,'Locations Data'!$B:$B,NC$5)>0,1,0) -> 1
B11: Bel Air, MD | C11: 0 | D11: =IF(SUMIFS('Locations Data'!$C:$C,'Locations Data'!$G:$G,$B11,'Locations Data'!$B:$B,D$5)>0,1,0) -> 1 | E11: =IF(SUMIFS('Locations Data'!$C:$C,'Locations Data'!$G:$G,$B11,'Locations Data'!$B:$B,E$5)>0,1,0) -> 1 | F11: =IF(SUMIFS('Locations Data'!$C:$C,'Locations Data'!$G:$G,$B11,'Locations Data'!$B:$B,F$5)>0,1,0) -> 0 | G11: =IF(SUMIFS('Locations Data'!$C:$C,'Locations Data'!$G:$G,$B11,'Locations Data'!$B:$B,G$5)>0,1,0) -> 0 | H11: =IF(SUMIFS('Locations Data'!$C:$C,'Locations Data'!$G:$G,$B11,'Locations Data'!$B:$B,H$5)>0,1,0) -> 1 | I11: =IF(SUMIFS('Locations Data'!$C:$C,'Locations Data'!$G:$G,$B11,'Locations Data'!$B:$B,I$5)>0,1,0) -> 1 | J11: =IF(SUMIFS('Locations Data'!$C:$C,'Locations Data'!$G:$G,$B11,'Locations Data'!$B:$B,J$5)>0,1,0) -> 1 | K11: =IF(SUMIFS('Locations Data'!$C:$C,'Locations Data'!$G:$G,$B11,'Locations Data'!$B:$B,K$5)>0,1,0) -> 1 | ... MV11: =IF(SUMIFS('Locations Data'!$C:$C,'Locations Data'!$G:$G,$B11,'Locations Data'!$B:$B,MV$5)>0,1,0) -> 1 | MW11: 0 | MX11: =IF(SUMIFS('Locations Data'!$C:$C,'Locations Data'!$G:$G,$B11,'Locations Data'!$B:$B,MX$5)>0,1,0) -> 1 | MY11: =IF(SUMIFS('Locations Data'!$C:$C,'Locations Data'!$G:$G,$B11,'Locations Data'!$B:$B,MY$5)>0,1,0) -> 0 | MZ11: =IF(SUMIFS('Locations Data'!$C:$C,'Locations Data'!$G:$G,$B11,'Locations Data'!$B:$B,MZ$5)>0,1,0) -> 0 | NA11: =IF(SUMIFS('Locations Data'!$C:$C,'Locations Data'!$G:$G,$B11,'Locations Data'!$B:$B,NA$5)>0,1,0) -> 1 | NB11: =IF(SUMIFS('Locations Data'!$C:$C,'Locations Data'!$G:$G,$B11,'Locations Data'!$B:$B,NB$5)>0,1,0) -> 1 | NC11: =IF(SUMIFS('Locations Data'!$C:$C,'Locations Data'!$G:$G,$B11,'Locations Data'!$B:$B,NC$5)>0,1,0) -> 1
B12: Bridgewater, NJ | C12: 0 | D12: =IF(SUMIFS('Locations Data'!$C:$C,'Locations Data'!$G:$G,$B12,'Locations Data'!$B:$B,D$5)>0,1,0) -> 1 | E12: =IF(SUMIFS('Locations Data'!$C:$C,'Locations Data'!$G:$G,$B12,'Locations Data'!$B:$B,E$5)>0,1,0) -> 1 | F12: =IF(SUMIFS('Locations Data'!$C:$C,'Locations Data'!$G:$G,$B12,'Locations Data'!$B:$B,F$5)>0,1,0) -> 0 | G12: =IF(SUMIFS('Locations Data'!$C:$C,'Locations Data'!$G:$G,$B12,'Locations Data'!$B:$B,G$5)>0,1,0) -> 0 | H12: =IF(SUMIFS('Locations Data'!$C:$C,'Locations Data'!$G:$G,$B12,'Locations Data'!$B:$B,H$5)>0,1,0) -> 1 | I12: =IF(SUMIFS('Locations Data'!$C:$C,'Locations Data'!$G:$G,$B12,'Locations Data'!$B:$B,I$5)>0,1,0) -> 1 | J12: =IF(SUMIFS('Locations Data'!$C:$C,'Locations Data'!$G:$G,$B12,'Locations Data'!$B:$B,J$5)>0,1,0) -> 1 | K12: =IF(SUMIFS('Locations Data'!$C:$C,'Locations Data'!$G:$G,$B12,'Locations Data'!$B:$B,K$5)>0,1,0) -> 1 | ... MV12: =IF(SUMIFS('Locations Data'!$C:$C,'Locations Data'!$G:$G,$B12,'Locations Data'!$B:$B,MV$5)>0,1,0) -> 1 | MW12: 0 | MX12: =IF(SUMIFS('Locations Data'!$C:$C,'Locations Data'!$G:$G,$B12,'Locations Data'!$B:$B,MX$5)>0,1,0) -> 1 | MY12: =IF(SUMIFS('Locations Data'!$C:$C,'Locations Data'!$G:$G,$B12,'Locations Data'!$B:$B,MY$5)>0,1,0) -> 0 | MZ12: =IF(SUMIFS('Locations Data'!$C:$C,'Locations Data'!$G:$G,$B12,'Locations Data'!$B:$B,MZ$5)>0,1,0) -> 0 | NA12: =IF(SUMIFS('Locations Data'!$C:$C,'Locations Data'!$G:$G,$B12,'Locations Data'!$B:$B,NA$5)>0,1,0) -> 1 | NB12: =IF(SUMIFS('Locations Data'!$C:$C,'Locations Data'!$G:$G,$B12,'Locations Data'!$B:$B,NB$5)>0,1,0) -> 1 | NC12: =IF(SUMIFS('Locations Data'!$C:$C,'Locations Data'!$G:$G,$B12,'Locations Data'!$B:$B,NC$5)>0,1,0) -> 1
B13: Frederick, MD | C13: 0 | D13: =IF(SUMIFS('Locations Data'!$C:$C,'Locations Data'!$G:$G,$B13,'Locations Data'!$B:$B,D$5)>0,1,0) -> 1 | E13: =IF(SUMIFS('Locations Data'!$C:$C,'Locations Data'!$G:$G,$B13,'Locations Data'!$B:$B,E$5)>0,1,0) -> 1 | F13: =IF(SUMIFS('Locations Data'!$C:$C,'Locations Data'!$G:$G,$B13,'Locations Data'!$B:$B,F$5)>0,1,0) -> 0 | G13: =IF(SUMIFS('Locations Data'!$C:$C,'Locations Data'!$G:$G,$B13,'Locations Data'!$B:$B,G$5)>0,1,0) -> 1 | H13: =IF(SUMIFS('Locations Data'!$C:$C,'Locations Data'!$G:$G,$B13,'Locations Data'!$B:$B,H$5)>0,1,0) -> 1 | I13: =IF(SUMIFS('Locations Data'!$C:$C,'Locations Data'!$G:$G,$B13,'Locations Data'!$B:$B,I$5)>0,1,0) -> 1 | J13: =IF(SUMIFS('Locations Data'!$C:$C,'Locations Data'!$G:$G,$B13,'Locations Data'!$B:$B,J$5)>0,1,0) -> 1 | K13: =IF(SUMIFS('Locations Data'!$C:$C,'Locations Data'!$G:$G,$B13,'Locations Data'!$B:$B,K$5)>0,1,0) -> 1 | ... MV13: =IF(SUMIFS('Locations Data'!$C:$C,'Locations Data'!$G:$G,$B13,'Locations Data'!$B:$B,MV$5)>0,1,0) -> 1 | MW13: 0 | MX13: =IF(SUMIFS('Locations Data'!$C:$C,'Locations Data'!$G:$G,$B13,'Locations Data'!$B:$B,MX$5)>0,1,0) -> 1 | MY13: =IF(SUMIFS('Locations Data'!$C:$C,'Locations Data'!$G:$G,$B13,'Locations Data'!$B:$B,MY$5)>0,1,0) -> 0 | MZ13: =IF(SUMIFS('Locations Data'!$C:$C,'Locations Data'!$G:$G,$B13,'Locations Data'!$B:$B,MZ$5)>0,1,0) -> 1 | NA13: =IF(SUMIFS('Locations Data'!$C:$C,'Locations Data'!$G:$G,$B13,'Locations Data'!$B:$B,NA$5)>0,1,0) -> 1 | NB13: =IF(SUMIFS('Locations Data'!$C:$C,'Locations Data'!$G:$G,$B13,'Locations Data'!$B:$B,NB$5)>0,1,0) -> 1 | NC13: =IF(SUMIFS('Locations Data'!$C:$C,'Locations Data'!$G:$G,$B13,'Locations Data'!$B:$B,NC$5)>0,1,0) -> 1
B14: Lancaster, PA | C14: 0 | D14: =IF(SUMIFS('Locations Data'!$C:$C,'Locations Data'!$G:$G,$B14,'Locations Data'!$B:$B,D$5)>0,1,0) -> 1 | E14: =IF(SUMIFS('Locations Data'!$C:$C,'Locations Data'!$G:$G,$B14,'Locations Data'!$B:$B,E$5)>0,1,0) -> 1 | F14: =IF(SUMIFS('Locations Data'!$C:$C,'Locations Data'!$G:$G,$B14,'Locations Data'!$B:$B,F$5)>0,1,0) -> 0 | G14: =IF(SUMIFS('Locations Data'!$C:$C,'Locations Data'!$G:$G,$B14,'Locations Data'!$B:$B,G$5)>0,1,0) -> 0 | H14: =IF(SUMIFS('Locations Data'!$C:$C,'Locations Data'!$G:$G,$B14,'Locations Data'!$B:$B,H$5)>0,1,0) -> 1 | I14: =IF(SUMIFS('Locations Data'!$C:$C,'Locations Data'!$G:$G,$B14,'Locations Data'!$B:$B,I$5)>0,1,0) -> 1 | J14: =IF(SUMIFS('Locations Data'!$C:$C,'Locations Data'!$G:$G,$B14,'Locations Data'!$B:$B,J$5)>0,1,0) -> 1 | K14: =IF(SUMIFS('Locations Data'!$C:$C,'Locations Data'!$G:$G,$B14,'Locations Data'!$B:$B,K$5)>0,1,0) -> 1 | ... MV14: =IF(SUMIFS('Locations Data'!$C:$C,'Locations Data'!$G:$G,$B14,'Locations Data'!$B:$B,MV$5)>0,1,0) -> 1 | MW14: 0 | MX14: =IF(SUMIFS('Locations Data'!$C:$C,'Locations Data'!$G:$G,$B14,'Locations Data'!$B:$B,MX$5)>0,1,0) -> 1 | MY14: =IF(SUMIFS('Locations Data'!$C:$C,'Locations Data'!$G:$G,$B14,'Locations Data'!$B:$B,MY$5)>0,1,0) -> 0 | MZ14: =IF(SUMIFS('Locations Data'!$C:$C,'Locations Data'!$G:$G,$B14,'Locations Data'!$B:$B,MZ$5)>0,1,0) -> 0 | NA14: =IF(SUMIFS('Locations Data'!$C:$C,'Locations Data'!$G:$G,$B14,'Locations Data'!$B:$B,NA$5)>0,1,0) -> 1 | NB14: =IF(SUMIFS('Locations Data'!$C:$C,'Locations Data'!$G:$G,$B14,'Locations Data'!$B:$B,NB$5)>0,1,0) -> 1 | NC14: =IF(SUMIFS('Locations Data'!$C:$C,'Locations Data'!$G:$G,$B14,'Locations Data'!$B:$B,NC$5)>0,1,0) -> 1
B15: Montclair, NJ | C15: 0 | D15: =IF(SUMIFS('Locations Data'!$C:$C,'Locations Data'!$G:$G,$B15,'Locations Data'!$B:$B,D$5)>0,1,0) -> 1 | E15: =IF(SUMIFS('Locations Data'!$C:$C,'Locations Data'!$G:$G,$B15,'Locations Data'!$B:$B,E$5)>0,1,0) -> 1 | F15: =IF(SUMIFS('Locations Data'!$C:$C,'Locations Data'!$G:$G,$B15,'Locations Data'!$B:$B,F$5)>0,1,0) -> 0 | G15: =IF(SUMIFS('Locations Data'!$C:$C,'Locations Data'!$G:$G,$B15,'Locations Data'!$B:$B,G$5)>0,1,0) -> 1 | H15: =IF(SUMIFS('Locations Data'!$C:$C,'Locations Data'!$G:$G,$B15,'Locations Data'!$B:$B,H$5)>0,1,0) -> 1 | I15: =IF(SUMIFS('Locations Data'!$C:$C,'Locations Data'!$G:$G,$B15,'Locations Data'!$B:$B,I$5)>0,1,0) -> 1 | J15: =IF(SUMIFS('Locations Data'!$C:$C,'Locations Data'!$G:$G,$B15,'Locations Data'!$B:$B,J$5)>0,1,0) -> 1 | K15: =IF(SUMIFS('Locations Data'!$C:$C,'Locations Data'!$G:$G,$B15,'Locations Data'!$B:$B,K$5)>0,1,0) -> 1 | ... MV15: =IF(SUMIFS('Locations Data'!$C:$C,'Locations Data'!$G:$G,$B15,'Locations Data'!$B:$B,MV$5)>0,1,0) -> 1 | MW15: 0 | MX15: =IF(SUMIFS('Locations Data'!$C:$C,'Locations Data'!$G:$G,$B15,'Locations Data'!$B:$B,MX$5)>0,1,0) -> 1 | MY15: =IF(SUMIFS('Locations Data'!$C:$C,'Locations Data'!$G:$G,$B15,'Locations Data'!$B:$B,MY$5)>0,1,0) -> 0 | MZ15: =IF(SUMIFS('Locations Data'!$C:$C,'Locations Data'!$G:$G,$B15,'Locations Data'!$B:$B,MZ$5)>0,1,0) -> 1 | NA15: =IF(SUMIFS('Locations Data'!$C:$C,'Locations Data'!$G:$G,$B15,'Locations Data'!$B:$B,NA$5)>0,1,0) -> 1 | NB15: =IF(SUMIFS('Locations Data'!$C:$C,'Locations Data'!$G:$G,$B15,'Locations Data'!$B:$B,NB$5)>0,1,0) -> 1 | NC15: =IF(SUMIFS('Locations Data'!$C:$C,'Locations Data'!$G:$G,$B15,'Locations Data'!$B:$B,NC$5)>0,1,0) -> 1
B16: Old Bridge, NJ | C16: 0 | D16: =IF(SUMIFS('Locations Data'!$C:$C,'Locations Data'!$G:$G,$B16,'Locations Data'!$B:$B,D$5)>0,1,0) -> 1 | E16: =IF(SUMIFS('Locations Data'!$C:$C,'Locations Data'!$G:$G,$B16,'Locations Data'!$B:$B,E$5)>0,1,0) -> 1 | F16: =IF(SUMIFS('Locations Data'!$C:$C,'Locations Data'!$G:$G,$B16,'Locations Data'!$B:$B,F$5)>0,1,0) -> 0 | G16: =IF(SUMIFS('Locations Data'!$C:$C,'Locations Data'!$G:$G,$B16,'Locations Data'!$B:$B,G$5)>0,1,0) -> 0 | H16: =IF(SUMIFS('Locations Data'!$C:$C,'Locations Data'!$G:$G,$B16,'Locations Data'!$B:$B,H$5)>0,1,0) -> 1 | I16: =IF(SUMIFS('Locations Data'!$C:$C,'Locations Data'!$G:$G,$B16,'Locations Data'!$B:$B,I$5)>0,1,0) -> 1 | J16: =IF(SUMIFS('Locations Data'!$C:$C,'Locations Data'!$G:$G,$B16,'Locations Data'!$B:$B,J$5)>0,1,0) -> 1 | K16: =IF(SUMIFS('Locations Data'!$C:$C,'Locations Data'!$G:$G,$B16,'Locations Data'!$B:$B,K$5)>0,1,0) -> 1 | ... MV16: =IF(SUMIFS('Locations Data'!$C:$C,'Locations Data'!$G:$G,$B16,'Locations Data'!$B:$B,MV$5)>0,1,0) -> 1 | MW16: 0 | MX16: =IF(SUMIFS('Locations Data'!$C:$C,'Locations Data'!$G:$G,$B16,'Locations Data'!$B:$B,MX$5)>0,1,0) -> 1 | MY16: =IF(SUMIFS('Locations Data'!$C:$C,'Locations Data'!$G:$G,$B16,'Locations Data'!$B:$B,MY$5)>0,1,0) -> 0 | MZ16: =IF(SUMIFS('Locations Data'!$C:$C,'Locations Data'!$G:$G,$B16,'Locations Data'!$B:$B,MZ$5)>0,1,0) -> 0 | NA16: =IF(SUMIFS('Locations Data'!$C:$C,'Locations Data'!$G:$G,$B16,'Locations Data'!$B:$B,NA$5)>0,1,0) -> 1 | NB16: =IF(SUMIFS('Locations Data'!$C:$C,'Locations Data'!$G:$G,$B16,'Locations Data'!$B:$B,NB$5)>0,1,0) -> 1 | NC16: =IF(SUMIFS('Locations Data'!$C:$C,'Locations Data'!$G:$G,$B16,'Locations Data'!$B:$B,NC$5)>0,1,0) -> 1
B17: Ridgewood, NJ | C17: 0 | D17: =IF(SUMIFS('Locations Data'!$C:$C,'Locations Data'!$G:$G,$B17,'Locations Data'!$B:$B,D$5)>0,1,0) -> 1 | E17: =IF(SUMIFS('Locations Data'!$C:$C,'Locations Data'!$G:$G,$B17,'Locations Data'!$B:$B,E$5)>0,1,0) -> 1 | F17: =IF(SUMIFS('Locations Data'!$C:$C,'Locations Data'!$G:$G,$B17,'Locations Data'!$B:$B,F$5)>0,1,0) -> 0 | G17: =IF(SUMIFS('Locations Data'!$C:$C,'Locations Data'!$G:$G,$B17,'Locations Data'!$B:$B,G$5)>0,1,0) -> 0 | H17: =IF(SUMIFS('Locations Data'!$C:$C,'Locations Data'!$G:$G,$B17,'Locations Data'!$B:$B,H$5)>0,1,0) -> 1 | I17: =IF(SUMIFS('Locations Data'!$C:$C,'Locations Data'!$G:$G,$B17,'Locations Data'!$B:$B,I$5)>0,1,0) -> 1 | J17: =IF(SUMIFS('Locations Data'!$C:$C,'Locations Data'!$G:$G,$B17,'Locations Data'!$B:$B,J$5)>0,1,0) -> 1 | K17: =IF(SUMIFS('Locations Data'!$C:$C,'Locations Data'!$G:$G,$B17,'Locations Data'!$B:$B,K$5)>0,1,0) -> 1 | ... MV17: =IF(SUMIFS('Locations Data'!$C:$C,'Locations Data'!$G:$G,$B17,'Locations Data'!$B:$B,MV$5)>0,1,0) -> 1 | MW17: 0 | MX17: =IF(SUMIFS('Locations Data'!$C:$C,'Locations Data'!$G:$G,$B17,'Locations Data'!$B:$B,MX$5)>0,1,0) -> 1 | MY17: =IF(SUMIFS('Locations Data'!$C:$C,'Locations Data'!$G:$G,$B17,'Locations Data'!$B:$B,MY$5)>0,1,0) -> 0 | MZ17: =IF(SUMIFS('Locations Data'!$C:$C,'Locations Data'!$G:$G,$B17,'Locations Data'!$B:$B,MZ$5)>0,1,0) -> 0 | NA17: =IF(SUMIFS('Locations Data'!$C:$C,'Locations Data'!$G:$G,$B17,'Locations Data'!$B:$B,NA$5)>0,1,0) -> 1 | NB17: =IF(SUMIFS('Locations Data'!$C:$C,'Locations Data'!$G:$G,$B17,'Locations Data'!$B:$B,NB$5)>0,1,0) -> 1 | NC17: =IF(SUMIFS('Locations Data'!$C:$C,'Locations Data'!$G:$G,$B17,'Locations Data'!$B:$B,NC$5)>0,1,0) -> 1
... B19: Waldorf, MD | C19: 0 | D19: =IF(SUMIFS('Locations Data'!$C:$C,'Locations Data'!$G:$G,$B19,'Locations Data'!$B:$B,D$5)>0,1,0) -> 1 | E19: =IF(SUMIFS('Locations Data'!$C:$C,'Locations Data'!$G:$G,$B19,'Locations Data'!$B:$B,E$5)>0,1,0) -> 1 | F19: =IF(SUMIFS('Locations Data'!$C:$C,'Locations Data'!$G:$G,$B19,'Locations Data'!$B:$B,F$5)>0,1,0) -> 0 | G19: =IF(SUMIFS('Locations Data'!$C:$C,'Locations Data'!$G:$G,$B19,'Locations Data'!$B:$B,G$5)>0,1,0) -> 0 | H19: =IF(SUMIFS('Locations Data'!$C:$C,'Locations Data'!$G:$G,$B19,'Locations Data'!$B:$B,H$5)>0,1,0) -> 1 | I19: =IF(SUMIFS('Locations Data'!$C:$C,'Locations Data'!$G:$G,$B19,'Locations Data'!$B:$B,I$5)>0,1,0) -> 1 | J19: =IF(SUMIFS('Locations Data'!$C:$C,'Locations Data'!$G:$G,$B19,'Locations Data'!$B:$B,J$5)>0,1,0) -> 1 | K19: =IF(SUMIFS('Locations Data'!$C:$C,'Locations Data'!$G:$G,$B19,'Locations Data'!$B:$B,K$5)>0,1,0) -> 1 | ... MV19: =IF(SUMIFS('Locations Data'!$C:$C,'Locations Data'!$G:$G,$B19,'Locations Data'!$B:$B,MV$5)>0,1,0) -> 1 | MW19: 0 | MX19: =IF(SUMIFS('Locations Data'!$C:$C,'Locations Data'!$G:$G,$B19,'Locations Data'!$B:$B,MX$5)>0,1,0) -> 1 | MY19: =IF(SUMIFS('Locations Data'!$C:$C,'Locations Data'!$G:$G,$B19,'Locations Data'!$B:$B,MY$5)>0,1,0) -> 0 | MZ19: =IF(SUMIFS('Locations Data'!$C:$C,'Locations Data'!$G:$G,$B19,'Locations Data'!$B:$B,MZ$5)>0,1,0) -> 0 | NA19: =IF(SUMIFS('Locations Data'!$C:$C,'Locations Data'!$G:$G,$B19,'Locations Data'!$B:$B,NA$5)>0,1,0) -> 1 | NB19: =IF(SUMIFS('Locations Data'!$C:$C,'Locations Data'!$G:$G,$B19,'Locations Data'!$B:$B,NB$5)>0,1,0) -> 1 | NC19: =IF(SUMIFS('Locations Data'!$C:$C,'Locations Data'!$G:$G,$B19,'Locations Data'!$B:$B,NC$5)>0,1,0) -> 1
B20: 0 | C20: 0 | D20: =IF(SUMIFS('Locations Data'!$C:$C,'Locations Data'!$G:$G,$B20,'Locations Data'!$B:$B,D$5)>0,1,0) -> 0 | E20: =IF(SUMIFS('Locations Data'!$C:$C,'Locations Data'!$G:$G,$B20,'Locations Data'!$B:$B,E$5)>0,1,0) -> 0 | F20: =IF(SUMIFS('Locations Data'!$C:$C,'Locations Data'!$G:$G,$B20,'Locations Data'!$B:$B,F$5)>0,1,0) -> 0 | G20: =IF(SUMIFS('Locations Data'!$C:$C,'Locations Data'!$G:$G,$B20,'Locations Data'!$B:$B,G$5)>0,1,0) -> 0 | H20: =IF(SUMIFS('Locations Data'!$C:$C,'Locations Data'!$G:$G,$B20,'Locations Data'!$B:$B,H$5)>0,1,0) -> 0 | I20: =IF(SUMIFS('Locations Data'!$C:$C,'Locations Data'!$G:$G,$B20,'Locations Data'!$B:$B,I$5)>0,1,0) -> 0 | J20: =IF(SUMIFS('Locations Data'!$C:$C,'Locations Data'!$G:$G,$B20,'Locations Data'!$B:$B,J$5)>0,1,0) -> 0 | K20: =IF(SUMIFS('Locations Data'!$C:$C,'Locations Data'!$G:$G,$B20,'Locations Data'!$B:$B,K$5)>0,1,0) -> 0 | ... MV20: =IF(SUMIFS('Locations Data'!$C:$C,'Locations Data'!$G:$G,$B20,'Locations Data'!$B:$B,MV$5)>0,1,0) -> 0 | MW20: 0 | MX20: =IF(SUMIFS('Locations Data'!$C:$C,'Locations Data'!$G:$G,$B20,'Locations Data'!$B:$B,MX$5)>0,1,0) -> 0 | MY20: =IF(SUMIFS('Locations Data'!$C:$C,'Locations Data'!$G:$G,$B20,'Locations Data'!$B:$B,MY$5)>0,1,0) -> 0 | MZ20: =IF(SUMIFS('Locations Data'!$C:$C,'Locations Data'!$G:$G,$B20,'Locations Data'!$B:$B,MZ$5)>0,1,0) -> 0 | NA20: =IF(SUMIFS('Locations Data'!$C:$C,'Locations Data'!$G:$G,$B20,'Locations Data'!$B:$B,NA$5)>0,1,0) -> 0 | NB20: =IF(SUMIFS('Locations Data'!$C:$C,'Locations Data'!$G:$G,$B20,'Locations Data'!$B:$B,NB$5)>0,1,0) -> 0 | NC20: =IF(SUMIFS('Locations Data'!$C:$C,'Locations Data'!$G:$G,$B20,'Locations Data'!$B:$B,NC$5)>0,1,0) -> 0
B21: 0 | C21: 0 | D21: =IF(SUMIFS('Locations Data'!$C:$C,'Locations Data'!$G:$G,$B21,'Locations Data'!$B:$B,D$5)>0,1,0) -> 0 | E21: =IF(SUMIFS('Locations Data'!$C:$C,'Locations Data'!$G:$G,$B21,'Locations Data'!$B:$B,E$5)>0,1,0) -> 0 | F21: =IF(SUMIFS('Locations Data'!$C:$C,'Locations Data'!$G:$G,$B21,'Locations Data'!$B:$B,F$5)>0,1,0) -> 0 | G21: =IF(SUMIFS('Locations Data'!$C:$C,'Locations Data'!$G:$G,$B21,'Locations Data'!$B:$B,G$5)>0,1,0) -> 0 | H21: =IF(SUMIFS('Locations Data'!$C:$C,'Locations Data'!$G:$G,$B21,'Locations Data'!$B:$B,H$5)>0,1,0) -> 0 | I21: =IF(SUMIFS('Locations Data'!$C:$C,'Locations Data'!$G:$G,$B21,'Locations Data'!$B:$B,I$5)>0,1,0) -> 0 | J21: =IF(SUMIFS('Locations Data'!$C:$C,'Locations Data'!$G:$G,$B21,'Locations Data'!$B:$B,J$5)>0,1,0) -> 0 | K21: =IF(SUMIFS('Locations Data'!$C:$C,'Locations Data'!$G:$G,$B21,'Locations Data'!$B:$B,K$5)>0,1,0) -> 0 | ... MV21: =IF(SUMIFS('Locations Data'!$C:$C,'Locations Data'!$G:$G,$B21,'Locations Data'!$B:$B,MV$5)>0,1,0) -> 0 | MW21: 0 | MX21: =IF(SUMIFS('Locations Data'!$C:$C,'Locations Data'!$G:$G,$B21,'Locations Data'!$B:$B,MX$5)>0,1,0) -> 0 | MY21: =IF(SUMIFS('Locations Data'!$C:$C,'Locations Data'!$G:$G,$B21,'Locations Data'!$B:$B,MY$5)>0,1,0) -> 0 | MZ21: =IF(SUMIFS('Locations Data'!$C:$C,'Locations Data'!$G:$G,$B21,'Locations Data'!$B:$B,MZ$5)>0,1,0) -> 0 | NA21: =IF(SUMIFS('Locations Data'!$C:$C,'Locations Data'!$G:$G,$B21,'Locations Data'!$B:$B,NA$5)>0,1,0) -> 0 | NB21: =IF(SUMIFS('Locations Data'!$C:$C,'Locations Data'!$G:$G,$B21,'Locations Data'!$B:$B,NB$5)>0,1,0) -> 0 | NC21: =IF(SUMIFS('Locations Data'!$C:$C,'Locations Data'!$G:$G,$B21,'Locations Data'!$B:$B,NC$5)>0,1,0) -> 0
B25: Monthly | C25: =EOMONTH(C3,0) -> 46053 | D25: =EOMONTH(C25,1) -> 46081 | E25: =EOMONTH(D25,1) -> 46112 | F25: =EOMONTH(E25,1) -> 46142 | G25: =EOMONTH(F25,1) -> 46173 | H25: =EOMONTH(G25,1) -> 46203 | I25: =EOMONTH(H25,1) -> 46234 | J25: =EOMONTH(I25,1) -> 46265 | K25: =EOMONTH(J25,1) -> 46295 | ... N25: =EOMONTH(M25,1) -> 46387
B28: =B6 -> Denville, NJ | C28: =SUMIFS(6:6,$2:$2,C$25) -> 26 | D28: =SUMIFS(6:6,$2:$2,D$25) -> 24 | E28: =SUMIFS(6:6,$2:$2,E$25) -> 26 | F28: =SUMIFS(6:6,$2:$2,F$25) -> 26 | G28: =SUMIFS(6:6,$2:$2,G$25) -> 26 | H28: =SUMIFS(6:6,$2:$2,H$25) -> 26 | I28: =SUMIFS(6:6,$2:$2,I$25) -> 27 | J28: =SUMIFS(6:6,$2:$2,J$25) -> 26 | ... N28: =SUMIFS(6:6,$2:$2,N$25) -> 26
B29: =B7 -> Hoboken, NJ | C29: =SUMIFS(7:7,$2:$2,C$25) -> 26 | D29: =SUMIFS(7:7,$2:$2,D$25) -> 24 | E29: =SUMIFS(7:7,$2:$2,E$25) -> 26 | F29: =SUMIFS(7:7,$2:$2,F$25) -> 26 | G29: =SUMIFS(7:7,$2:$2,G$25) -> 26 | H29: =SUMIFS(7:7,$2:$2,H$25) -> 26 | I29: =SUMIFS(7:7,$2:$2,I$25) -> 27 | J29: =SUMIFS(7:7,$2:$2,J$25) -> 26 | ... N29: =SUMIFS(7:7,$2:$2,N$25) -> 26
B30: =B8 -> Jersey City, NJ | C30: =SUMIFS(8:8,$2:$2,C$25) -> 26 | D30: =SUMIFS(8:8,$2:$2,D$25) -> 24 | E30: =SUMIFS(8:8,$2:$2,E$25) -> 26 | F30: =SUMIFS(8:8,$2:$2,F$25) -> 26 | G30: =SUMIFS(8:8,$2:$2,G$25) -> 26 | H30: =SUMIFS(8:8,$2:$2,H$25) -> 26 | I30: =SUMIFS(8:8,$2:$2,I$25) -> 27 | J30: =SUMIFS(8:8,$2:$2,J$25) -> 26 | ... N30: =SUMIFS(8:8,$2:$2,N$25) -> 26
B31: =B9 -> Red Bank, NJ | C31: =SUMIFS(9:9,$2:$2,C$25) -> 22 | D31: =SUMIFS(9:9,$2:$2,D$25) -> 20 | E31: =SUMIFS(9:9,$2:$2,E$25) -> 21 | F31: =SUMIFS(9:9,$2:$2,F$25) -> 22 | G31: =SUMIFS(9:9,$2:$2,G$25) -> 22 | H31: =SUMIFS(9:9,$2:$2,H$25) -> 21 | I31: =SUMIFS(9:9,$2:$2,I$25) -> 23 | J31: =SUMIFS(9:9,$2:$2,J$25) -> 21 | ... N31: =SUMIFS(9:9,$2:$2,N$25) -> 22
B32: =B10 -> Tribeca, NY | C32: =SUMIFS(10:10,$2:$2,C$25) -> 21 | D32: =SUMIFS(10:10,$2:$2,D$25) -> 20 | E32: =SUMIFS(10:10,$2:$2,E$25) -> 22 | F32: =SUMIFS(10:10,$2:$2,F$25) -> 22 | G32: =SUMIFS(10:10,$2:$2,G$25) -> 21 | H32: =SUMIFS(10:10,$2:$2,H$25) -> 22 | I32: =SUMIFS(10:10,$2:$2,I$25) -> 23 | J32: =SUMIFS(10:10,$2:$2,J$25) -> 21 | ... N32: =SUMIFS(10:10,$2:$2,N$25) -> 22
B33: =B11 -> Bel Air, MD | C33: =SUMIFS(11:11,$2:$2,C$25) -> 22 | D33: =SUMIFS(11:11,$2:$2,D$25) -> 20 | E33: =SUMIFS(11:11,$2:$2,E$25) -> 21 | F33: =SUMIFS(11:11,$2:$2,F$25) -> 22 | G33: =SUMIFS(11:11,$2:$2,G$25) -> 22 | H33: =SUMIFS(11:11,$2:$2,H$25) -> 21 | I33: =SUMIFS(11:11,$2:$2,I$25) -> 23 | J33: =SUMIFS(11:11,$2:$2,J$25) -> 21 | ... N33: =SUMIFS(11:11,$2:$2,N$25) -> 22
B34: =B12 -> Bridgewater, NJ | C34: =SUMIFS(12:12,$2:$2,C$25) -> 22 | D34: =SUMIFS(12:12,$2:$2,D$25) -> 20 | E34: =SUMIFS(12:12,$2:$2,E$25) -> 21 | F34: =SUMIFS(12:12,$2:$2,F$25) -> 22 | G34: =SUMIFS(12:12,$2:$2,G$25) -> 22 | H34: =SUMIFS(12:12,$2:$2,H$25) -> 21 | I34: =SUMIFS(12:12,$2:$2,I$25) -> 23 | J34: =SUMIFS(12:12,$2:$2,J$25) -> 21 | ... N34: =SUMIFS(12:12,$2:$2,N$25) -> 22
B35: =B13 -> Frederick, MD | C35: =SUMIFS(13:13,$2:$2,C$25) -> 26 | D35: =SUMIFS(13:13,$2:$2,D$25) -> 24 | E35: =SUMIFS(13:13,$2:$2,E$25) -> 26 | F35: =SUMIFS(13:13,$2:$2,F$25) -> 26 | G35: =SUMIFS(13:13,$2:$2,G$25) -> 26 | H35: =SUMIFS(13:13,$2:$2,H$25) -> 26 | I35: =SUMIFS(13:13,$2:$2,I$25) -> 27 | J35: =SUMIFS(13:13,$2:$2,J$25) -> 26 | ... N35: =SUMIFS(13:13,$2:$2,N$25) -> 26
B36: =B14 -> Lancaster, PA | C36: =SUMIFS(14:14,$2:$2,C$25) -> 22 | D36: =SUMIFS(14:14,$2:$2,D$25) -> 20 | E36: =SUMIFS(14:14,$2:$2,E$25) -> 21 | F36: =SUMIFS(14:14,$2:$2,F$25) -> 22 | G36: =SUMIFS(14:14,$2:$2,G$25) -> 22 | H36: =SUMIFS(14:14,$2:$2,H$25) -> 21 | I36: =SUMIFS(14:14,$2:$2,I$25) -> 23 | J36: =SUMIFS(14:14,$2:$2,J$25) -> 21 | ... N36: =SUMIFS(14:14,$2:$2,N$25) -> 22
B37: =B15 -> Montclair, NJ | C37: =SUMIFS(15:15,$2:$2,C$25) -> 26 | D37: =SUMIFS(15:15,$2:$2,D$25) -> 24 | E37: =SUMIFS(15:15,$2:$2,E$25) -> 26 | F37: =SUMIFS(15:15,$2:$2,F$25) -> 26 | G37: =SUMIFS(15:15,$2:$2,G$25) -> 26 | H37: =SUMIFS(15:15,$2:$2,H$25) -> 26 | I37: =SUMIFS(15:15,$2:$2,I$25) -> 27 | J37: =SUMIFS(15:15,$2:$2,J$25) -> 26 | ... N37: =SUMIFS(15:15,$2:$2,N$25) -> 26
B38: =B16 -> Old Bridge, NJ | C38: =SUMIFS(16:16,$2:$2,C$25) -> 22 | D38: =SUMIFS(16:16,$2:$2,D$25) -> 20 | E38: =SUMIFS(16:16,$2:$2,E$25) -> 21 | F38: =SUMIFS(16:16,$2:$2,F$25) -> 22 | G38: =SUMIFS(16:16,$2:$2,G$25) -> 22 | H38: =SUMIFS(16:16,$2:$2,H$25) -> 21 | I38: =SUMIFS(16:16,$2:$2,I$25) -> 23 | J38: =SUMIFS(16:16,$2:$2,J$25) -> 21 | ... N38: =SUMIFS(16:16,$2:$2,N$25) -> 22
B39: =B17 -> Ridgewood, NJ | C39: =SUMIFS(17:17,$2:$2,C$25) -> 22 | D39: =SUMIFS(17:17,$2:$2,D$25) -> 20 | E39: =SUMIFS(17:17,$2:$2,E$25) -> 21 | F39: =SUMIFS(17:17,$2:$2,F$25) -> 22 | G39: =SUMIFS(17:17,$2:$2,G$25) -> 22 | H39: =SUMIFS(17:17,$2:$2,H$25) -> 21 | I39: =SUMIFS(17:17,$2:$2,I$25) -> 23 | J39: =SUMIFS(17:17,$2:$2,J$25) -> 21 | ... N39: =SUMIFS(17:17,$2:$2,N$25) -> 22
B40: =B18 -> Short Hills, NJ | C40: =SUMIFS(18:18,$2:$2,C$25) -> 22 | D40: =SUMIFS(18:18,$2:$2,D$25) -> 20 | E40: =SUMIFS(18:18,$2:$2,E$25) -> 21 | F40: =SUMIFS(18:18,$2:$2,F$25) -> 22 | G40: =SUMIFS(18:18,$2:$2,G$25) -> 22 | H40: =SUMIFS(18:18,$2:$2,H$25) -> 21 | I40: =SUMIFS(18:18,$2:$2,I$25) -> 23 | J40: =SUMIFS(18:18,$2:$2,J$25) -> 21 | ... N40: =SUMIFS(18:18,$2:$2,N$25) -> 22
B41: =B19 -> Waldorf, MD | C41: =SUMIFS(19:19,$2:$2,C$25) -> 22 | D41: =SUMIFS(19:19,$2:$2,D$25) -> 20 | E41: =SUMIFS(19:19,$2:$2,E$25) -> 21 | F41: =SUMIFS(19:19,$2:$2,F$25) -> 22 | G41: =SUMIFS(19:19,$2:$2,G$25) -> 22 | H41: =SUMIFS(19:19,$2:$2,H$25) -> 21 | I41: =SUMIFS(19:19,$2:$2,I$25) -> 23 | J41: =SUMIFS(19:19,$2:$2,J$25) -> 21 | ... N41: =SUMIFS(19:19,$2:$2,N$25) -> 22
B42: =B20 -> 0 | C42: =SUMIFS(20:20,$2:$2,C$25) -> 0 | D42: =SUMIFS(20:20,$2:$2,D$25) -> 0 | E42: =SUMIFS(20:20,$2:$2,E$25) -> 0 | F42: =SUMIFS(20:20,$2:$2,F$25) -> 0 | G42: =SUMIFS(20:20,$2:$2,G$25) -> 0 | H42: =SUMIFS(20:20,$2:$2,H$25) -> 0 | I42: =SUMIFS(20:20,$2:$2,I$25) -> 0 | J42: =SUMIFS(20:20,$2:$2,J$25) -> 0 | ... N42: =SUMIFS(20:20,$2:$2,N$25) -> 0
B43: =B21 -> 0 | C43: =SUMIFS(21:21,$2:$2,C$25) -> 0 | D43: =SUMIFS(21:21,$2:$2,D$25) -> 0 | E43: =SUMIFS(21:21,$2:$2,E$25) -> 0 | F43: =SUMIFS(21:21,$2:$2,F$25) -> 0 | G43: =SUMIFS(21:21,$2:$2,G$25) -> 0 | H43: =SUMIFS(21:21,$2:$2,H$25) -> 0 | I43: =SUMIFS(21:21,$2:$2,I$25) -> 0 | J43: =SUMIFS(21:21,$2:$2,J$25) -> 0 | ... N43: =SUMIFS(21:21,$2:$2,N$25) -> 0

Sheet Locations Data
A1: Location | B1: Week Day | C1: Hours / Day | D1: Beak Hours / Day / Room | E1: Provider Rooms | F1: Esti Rooms | G1: Adj. Location | K1: Locations List | M1: Months
A2: Hoboken | B2: Monday | C2: 8 | D2: 0.5 | E2: 6 | F2: 2 | G2: =_xlfn.XLOOKUP(A2,$J$3:$J$17,$K$3:$K$17) -> Hoboken, NJ | K2: [SELECT] | M2: [SELECT] | O2: Body Contouring | P2: Esti
A3: Hoboken | B3: Tuesday | C3: 9 | D3: 0.5 | E3: 6 | F3: 2 | G3: =_xlfn.XLOOKUP(A3,$J$3:$J$17,$K$3:$K$17) -> Hoboken, NJ | J3: Bel Air | K3: Bel Air, MD | M3: 45688 | O3: Facials | P3: Esti
A4: Hoboken | B4: Wednesday | C4: 10 | D4: 0.5 | E4: 6 | F4: 2 | G4: =_xlfn.XLOOKUP(A4,$J$3:$J$17,$K$3:$K$17) -> Hoboken, NJ | J4: Denville | K4: Denville, NJ | M4: =EOMONTH(M3,1) -> 45716 | O4: Filler | P4: Provider
A5: Hoboken | B5: Thursday | C5: 10 | D5: 0.5 | E5: 6 | F5: 2 | G5: =_xlfn.XLOOKUP(A5,$J$3:$J$17,$K$3:$K$17) -> Hoboken, NJ | J5: Frederick | K5: Frederick, MD | M5: =EOMONTH(M4,1) -> 45747 | O5: Laser Hair Removal | P5: Provider
A6: Hoboken | B6: Friday | C6: 8 | D6: 0.5 | E6: 6 | F6: 2 | G6: =_xlfn.XLOOKUP(A6,$J$3:$J$17,$K$3:$K$17) -> Hoboken, NJ | J6: Hoboken | K6: Hoboken, NJ | M6: =EOMONTH(M5,1) -> 45777 | O6: Neurotoxins | P6: Provider
A7: Hoboken | B7: Saturday | C7: 8 | D7: 0.5 | E7: 6 | F7: 2 | G7: =_xlfn.XLOOKUP(A7,$J$3:$J$17,$K$3:$K$17) -> Hoboken, NJ | J7: Jersey City | K7: Jersey City, NJ | M7: =EOMONTH(M6,1) -> 45808 | O7: PRF | P7: Provider
A8: Hoboken | B8: Sunday | C8: 0 | D8: 0 | E8: 6 | F8: 2 | G8: =_xlfn.XLOOKUP(A8,$J$3:$J$17,$K$3:$K$17) -> Hoboken, NJ | J8: Montclair | K8: Montclair, NJ | M8: =EOMONTH(M7,1) -> 45838 | O8: Skin Rejuvenation | P8: Provider
A9: Jersey City | B9: Monday | C9: 10 | D9: 0.5 | E9: 4 | F9: 1 | G9: =_xlfn.XLOOKUP(A9,$J$3:$J$17,$K$3:$K$17) -> Jersey City, NJ | J9: Old Bridge | K9: Old Bridge, NJ | M9: =EOMONTH(M8,1) -> 45869 | O9: Other Injectables | P9: Provider
A10: Jersey City | B10: Tuesday | C10: 10 | D10: 0.5 | E10: 4 | F10: 1 | G10: =_xlfn.XLOOKUP(A10,$J$3:$J$17,$K$3:$K$17) -> Jersey City, NJ | J10: Red Bank | K10: Red Bank, NJ | M10: =EOMONTH(M9,1) -> 45900 | O10: Other | P10: Provider
A11: Jersey City | B11: Wednesday | C11: 10 | D11: 0.5 | E11: 4 | F11: 1 | G11: =_xlfn.XLOOKUP(A11,$J$3:$J$17,$K$3:$K$17) -> Jersey City, NJ | J11: Ridgewood | K11: Ridgewood, NJ | M11: =EOMONTH(M10,1) -> 45930
A12: Jersey City | B12: Thursday | C12: 10 | D12: 0.5 | E12: 4 | F12: 1 | G12: =_xlfn.XLOOKUP(A12,$J$3:$J$17,$K$3:$K$17) -> Jersey City, NJ | J12: Scarsdale | K12: Scarsdale, NY | M12: =EOMONTH(M11,1) -> 45961
A13: Jersey City | B13: Friday | C13: 8 | D13: 0.5 | E13: 4 | F13: 1 | G13: =_xlfn.XLOOKUP(A13,$J$3:$J$17,$K$3:$K$17) -> Jersey City, NJ | J13: Short Hills | K13: Short Hills, NJ | M13: =EOMONTH(M12,1) -> 45991
A14: Jersey City | B14: Saturday | C14: 5 | D14: 0.5 | E14: 4 | F14: 1 | G14: =_xlfn.XLOOKUP(A14,$J$3:$J$17,$K$3:$K$17) -> Jersey City, NJ | J14: Tribeca | K14: Tribeca, NY | M14: =EOMONTH(M13,1) -> 46022
A15: Jersey City | B15: Sunday | C15: 0 | D15: 0 | E15: 4 | F15: 1 | G15: =_xlfn.XLOOKUP(A15,$J$3:$J$17,$K$3:$K$17) -> Jersey City, NJ | J15: Waldorf | K15: Waldorf, MD
A16: Montclair | B16: Monday | C16: 8 | D16: 0.5 | E16: 5 | F16: 1 | G16: =_xlfn.XLOOKUP(A16,$J$3:$J$17,$K$3:$K$17) -> Montclair, NJ | J16: Lancaster | K16: Lancaster, PA
A17: Montclair | B17: Tuesday | C17: 8 | D17: 0.5 | E17: 5 | F17: 1 | G17: =_xlfn.XLOOKUP(A17,$J$3:$J$17,$K$3:$K$17) -> Montclair, NJ | J17: Bridgewater | K17: Bridgewater, NJ
A18: Montclair | B18: Wednesday | C18: 10 | D18: 0.5 | E18: 5 | F18: 1 | G18: =_xlfn.XLOOKUP(A18,$J$3:$J$17,$K$3:$K$17) -> Montclair, NJ
A19: Montclair | B19: Thursday | C19: 10 | D19: 0.5 | E19: 5 | F19: 1 | G19: =_xlfn.XLOOKUP(A19,$J$3:$J$17,$K$3:$K$17) -> Montclair, NJ
A20: Montclair | B20: Friday | C20: 8 | D20: 0.5 | E20: 5 | F20: 1 | G20: =_xlfn.XLOOKUP(A20,$J$3:$J$17,$K$3:$K$17) -> Montclair, NJ
A21: Montclair | B21: Saturday | C21: 5 | D21: 0.5 | E21: 5 | F21: 1 | G21: =_xlfn.XLOOKUP(A21,$J$3:$J$17,$K$3:$K$17) -> Montclair, NJ
A22: Montclair | B22: Sunday | C22: 0 | D22: 0 | E22: 5 | F22: 1 | G22: =_xlfn.XLOOKUP(A22,$J$3:$J$17,$K$3:$K$17) -> Montclair, NJ
A23: Short Hills | B23: Monday | C23: 0 | D23: 0 | E23: 4 | F23: 1 | G23: =_xlfn.XLOOKUP(A23,$J$3:$J$17,$K$3:$K$17) -> Short Hills, NJ
A24: Short Hills | B24: Tuesday | C24: 8 | D24: 0.5 | E24: 4 | F24: 1 | G24: =_xlfn.XLOOKUP(A24,$J$3:$J$17,$K$3:$K$17) -> Short Hills, NJ
A25: Short Hills | B25: Wednesday | C25: 10 | D25: 0.5 | E25: 4 | F25: 1 | G25: =_xlfn.XLOOKUP(A25,$J$3:$J$17,$K$3:$K$17) -> Short Hills, NJ
A26: Short Hills | B26: Thursday | C26: 10 | D26: 0.5 | E26: 4 | F26: 1 | G26: =_xlfn.XLOOKUP(A26,$J$3:$J$17,$K$3:$K$17) -> Short Hills, NJ
A27: Short Hills | B27: Friday | C27: 8 | D27: 0.5 | E27: 4 | F27: 1 | G27: =_xlfn.XLOOKUP(A27,$J$3:$J$17,$K$3:$K$17) -> Short Hills, NJ
A28: Short Hills | B28: Saturday | C28: 5 | D28: 0.5 | E28: 4 | F28: 1 | G28: =_xlfn.XLOOKUP(A28,$J$3:$J$17,$K$3:$K$17) -> Short Hills, NJ
A29: Short Hills | B29: Sunday | C29: 0 | D29: 0 | E29: 4 | F29: 1 | G29: =_xlfn.XLOOKUP(A29,$J$3:$J$17,$K$3:$K$17) -> Short Hills, NJ
... A106: Lancaster | B106: Sunday | C106: 0 | D106: 0 | E106: 4 | F106: 1 | G106: =_xlfn.XLOOKUP(A106,$J$3:$J$17,$K$3:$K$17) -> Lancaster, PA
